<!-- Copyright 2021 DeepMind Technologies Limited

     Licensed under the Apache License, Version 2.0 (the "License");
     you may not use this file except in compliance with the License.
     You may obtain a copy of the License at

         http://www.apache.org/licenses/LICENSE-2.0

     Unless required by applicable law or agreed to in writing, software
     distributed under the License is distributed on an "AS IS" BASIS,
     WITHOUT WARRANTIES OR CONDITIONS OF ANY KIND, either express or implied.
     See the License for the specific language governing permissions and
     limitations under the License.
-->

<mujoco model="3-link arm">
  <option timestep="0.005" iterations="50" solver="Newton" tolerance="1e-10"/>

  <visual>
    <rgba haze=".3 .3 .3 1"/>
  </visual>

  <default>
    <joint type="hinge" pos="0 0 0" axis="0 0 1" limited="true" range="-5 170" damping="3"/>
  </default>

  <asset>
    <texture type="skybox" builtin="gradient" rgb1="0.6 0.6 0.6" rgb2="0 0 0" width="512" height="512"/>

    <texture name="texplane" type="2d" builtin="checker" rgb1=".25 .25 .25" rgb2=".3 .3 .3" width="512" height="512" mark="cross" markrgb=".8 .8 .8"/>

    <material name="matplane" reflectance="0.3" texture="texplane" texrepeat="1 1" texuniform="true"/>
  </asset>

  <worldbody>
    <body name="upper arm" pos="0 0 0">
      <geom name="upper arm" type="capsule" size="0.045" fromto="0 0 0  0.31 0 0" rgba=".5 .1 .1 1"/>
      <joint name="shoulder"/>
      <geom name="shoulder" type="cylinder" pos="0 0 0" size=".05 .05" rgba=".5 .1 .8 .5" mass="0" group="1"/>

      <body name="forearm" pos="0.31 0 0">
        <geom name="forearm" type="capsule" size="0.035" fromto="0 0 0  0.34 0 0" rgba=".5 .1 .1 1"/>
        <joint name="elbow"/>
        <geom name="elbow" type="cylinder" pos="0 0 0" size=".04 .05" rgba=".5 .1 .8 .5" mass="0" group="1"/>
        <body name="hand" pos="0.34 0 0">
          <geom name="hand" type="capsule" size="0.025" fromto="0 0 0  0.2 0 0" rgba=".5 .1 .1 1"/>
          <joint name="wrist"/>
          <geom name="wrist" type="cylinder" pos="0 0 0" size=".03 .05" rgba=".5 .1 .8 .5" mass="0" group="1"/>
          <body name="tip" pos="0.2 0 0">
            <geom name="tip" type="cylinder" pos="0 0 0" size=".03 .025" rgba=".5 .1 .8 .5" mass="0" group="1"/>
          </body>
        </body>
      </body>
    </body>

    <body name="IK" mocap="true" pos="0.85 0.01 0">
        <geom type="sphere" size="0.04" contype="0" conaffinity="0" rgba="0.8 0.4 0.4 0.2"/>
    </body>


    <geom name="floor" pos="0 0 -1.35" size="0 0 1" type="plane" material="matplane"/>

    <light directional="true" diffuse=".8 .8 .8" specular=".2 .2 .2" pos="0 0 5" dir="0 0 -1"/>
  </worldbody>

  <actuator>
    <motor name="shoulder" joint="shoulder" ctrllimited="true" ctrlrange="-100 100"/>
    <motor name="elbow" joint="elbow" ctrllimited="true" ctrlrange="-100 100"/>
  </actuator>

  <include file="cmu_model.xml"/>
</mujoco>
